2019-06-20 12:36:54,814 ERROR: Exception on /dashboard [GET] [in /Users/aisino/Projects/DockerManager/venv/lib/python3.7/site-packages/flask/app.py:1780]
Traceback (most recent call last):
  File "/Users/aisino/Projects/DockerManager/venv/lib/python3.7/site-packages/flask/app.py", line 2311, in wsgi_app
    response = self.full_dispatch_request()
  File "/Users/aisino/Projects/DockerManager/venv/lib/python3.7/site-packages/flask/app.py", line 1834, in full_dispatch_request
    rv = self.handle_user_exception(e)
  File "/Users/aisino/Projects/DockerManager/venv/lib/python3.7/site-packages/flask/app.py", line 1737, in handle_user_exception
    reraise(exc_type, exc_value, tb)
  File "/Users/aisino/Projects/DockerManager/venv/lib/python3.7/site-packages/flask/_compat.py", line 36, in reraise
    raise value
  File "/Users/aisino/Projects/DockerManager/venv/lib/python3.7/site-packages/flask/app.py", line 1832, in full_dispatch_request
    rv = self.dispatch_request()
  File "/Users/aisino/Projects/DockerManager/venv/lib/python3.7/site-packages/flask/app.py", line 1818, in dispatch_request
    return self.view_functions[rule.endpoint](**req.view_args)
  File "/Users/aisino/Projects/DockerManager/venv/lib/python3.7/site-packages/flask_login/utils.py", line 261, in decorated_view
    return func(*args, **kwargs)
  File "/Users/aisino/Projects/DockerManager/app/main/routes.py", line 42, in dashboard
    'networks_num'])
  File "/Users/aisino/Projects/DockerManager/venv/lib/python3.7/site-packages/flask/templating.py", line 135, in render_template
    context, ctx.app)
  File "/Users/aisino/Projects/DockerManager/venv/lib/python3.7/site-packages/flask/templating.py", line 117, in _render
    rv = template.render(context)
  File "/Users/aisino/Projects/DockerManager/venv/lib/python3.7/site-packages/jinja2/asyncsupport.py", line 76, in render
    return original_render(self, *args, **kwargs)
  File "/Users/aisino/Projects/DockerManager/venv/lib/python3.7/site-packages/jinja2/environment.py", line 1008, in render
    return self.environment.handle_exception(exc_info, True)
  File "/Users/aisino/Projects/DockerManager/venv/lib/python3.7/site-packages/jinja2/environment.py", line 780, in handle_exception
    reraise(exc_type, exc_value, tb)
  File "/Users/aisino/Projects/DockerManager/venv/lib/python3.7/site-packages/jinja2/_compat.py", line 37, in reraise
    raise value.with_traceback(tb)
  File "/Users/aisino/Projects/DockerManager/app/templates/dashboard.html", line 34, in top-level template code
    <td>{{ endpoint.db.name }} <span style="color: #d2d2d2">CPU:{{ endpoint.cpu_num }} MEMORY:{{ endpoint.mem_num }}GB - {{ endpoint.mode }} {{ endpoint.version }}</span></td>
  File "/Users/aisino/Projects/DockerManager/venv/lib/python3.7/site-packages/jinja2/environment.py", line 430, in getattr
    return getattr(obj, attribute)
jinja2.exceptions.UndefinedError: 'dict object' has no attribute 'db'
2019-06-20 12:38:05,226 INFO: Aisino Docker Manager startup [in /Users/aisino/Projects/DockerManager/app/__init__.py:76]
2019-06-20 12:38:08,661 ERROR: Exception on /load/undefined [GET] [in /Users/aisino/Projects/DockerManager/venv/lib/python3.7/site-packages/flask/app.py:1780]
Traceback (most recent call last):
  File "/Users/aisino/Projects/DockerManager/venv/lib/python3.7/site-packages/flask/app.py", line 2311, in wsgi_app
    response = self.full_dispatch_request()
  File "/Users/aisino/Projects/DockerManager/venv/lib/python3.7/site-packages/flask/app.py", line 1834, in full_dispatch_request
    rv = self.handle_user_exception(e)
  File "/Users/aisino/Projects/DockerManager/venv/lib/python3.7/site-packages/flask/app.py", line 1737, in handle_user_exception
    reraise(exc_type, exc_value, tb)
  File "/Users/aisino/Projects/DockerManager/venv/lib/python3.7/site-packages/flask/_compat.py", line 36, in reraise
    raise value
  File "/Users/aisino/Projects/DockerManager/venv/lib/python3.7/site-packages/flask/app.py", line 1832, in full_dispatch_request
    rv = self.dispatch_request()
  File "/Users/aisino/Projects/DockerManager/venv/lib/python3.7/site-packages/flask/app.py", line 1818, in dispatch_request
    return self.view_functions[rule.endpoint](**req.view_args)
  File "/Users/aisino/Projects/DockerManager/venv/lib/python3.7/site-packages/flask_login/utils.py", line 261, in decorated_view
    return func(*args, **kwargs)
  File "/Users/aisino/Projects/DockerManager/app/main/routes.py", line 51, in load_endpoint
    mode = services.get_endpoint_mode(endpoint_id)
  File "/Users/aisino/Projects/DockerManager/app/endpoint/services.py", line 58, in get_endpoint_mode
    client = docker_client(endpoint.url)
AttributeError: 'NoneType' object has no attribute 'url'
2019-06-20 12:38:17,031 ERROR: Exception on /load/undefined [GET] [in /Users/aisino/Projects/DockerManager/venv/lib/python3.7/site-packages/flask/app.py:1780]
Traceback (most recent call last):
  File "/Users/aisino/Projects/DockerManager/venv/lib/python3.7/site-packages/flask/app.py", line 2311, in wsgi_app
    response = self.full_dispatch_request()
  File "/Users/aisino/Projects/DockerManager/venv/lib/python3.7/site-packages/flask/app.py", line 1834, in full_dispatch_request
    rv = self.handle_user_exception(e)
  File "/Users/aisino/Projects/DockerManager/venv/lib/python3.7/site-packages/flask/app.py", line 1737, in handle_user_exception
    reraise(exc_type, exc_value, tb)
  File "/Users/aisino/Projects/DockerManager/venv/lib/python3.7/site-packages/flask/_compat.py", line 36, in reraise
    raise value
  File "/Users/aisino/Projects/DockerManager/venv/lib/python3.7/site-packages/flask/app.py", line 1832, in full_dispatch_request
    rv = self.dispatch_request()
  File "/Users/aisino/Projects/DockerManager/venv/lib/python3.7/site-packages/flask/app.py", line 1818, in dispatch_request
    return self.view_functions[rule.endpoint](**req.view_args)
  File "/Users/aisino/Projects/DockerManager/venv/lib/python3.7/site-packages/flask_login/utils.py", line 261, in decorated_view
    return func(*args, **kwargs)
  File "/Users/aisino/Projects/DockerManager/app/main/routes.py", line 51, in load_endpoint
    mode = services.get_endpoint_mode(endpoint_id)
  File "/Users/aisino/Projects/DockerManager/app/endpoint/services.py", line 58, in get_endpoint_mode
    client = docker_client(endpoint.url)
AttributeError: 'NoneType' object has no attribute 'url'
2019-06-20 12:39:34,927 INFO: Aisino Docker Manager startup [in /Users/aisino/Projects/DockerManager/app/__init__.py:76]
2019-06-20 12:39:42,081 ERROR: Exception on /load/undefined [GET] [in /Users/aisino/Projects/DockerManager/venv/lib/python3.7/site-packages/flask/app.py:1780]
Traceback (most recent call last):
  File "/Users/aisino/Projects/DockerManager/venv/lib/python3.7/site-packages/flask/app.py", line 2311, in wsgi_app
    response = self.full_dispatch_request()
  File "/Users/aisino/Projects/DockerManager/venv/lib/python3.7/site-packages/flask/app.py", line 1834, in full_dispatch_request
    rv = self.handle_user_exception(e)
  File "/Users/aisino/Projects/DockerManager/venv/lib/python3.7/site-packages/flask/app.py", line 1737, in handle_user_exception
    reraise(exc_type, exc_value, tb)
  File "/Users/aisino/Projects/DockerManager/venv/lib/python3.7/site-packages/flask/_compat.py", line 36, in reraise
    raise value
  File "/Users/aisino/Projects/DockerManager/venv/lib/python3.7/site-packages/flask/app.py", line 1832, in full_dispatch_request
    rv = self.dispatch_request()
  File "/Users/aisino/Projects/DockerManager/venv/lib/python3.7/site-packages/flask/app.py", line 1818, in dispatch_request
    return self.view_functions[rule.endpoint](**req.view_args)
  File "/Users/aisino/Projects/DockerManager/venv/lib/python3.7/site-packages/flask_login/utils.py", line 261, in decorated_view
    return func(*args, **kwargs)
  File "/Users/aisino/Projects/DockerManager/app/main/routes.py", line 51, in load_endpoint
    mode = services.get_endpoint_mode(endpoint_id)
  File "/Users/aisino/Projects/DockerManager/app/endpoint/services.py", line 58, in get_endpoint_mode
    client = docker_client(endpoint.url)
AttributeError: 'NoneType' object has no attribute 'url'
2019-06-20 12:45:15,143 INFO: Aisino Docker Manager startup [in /Users/aisino/Projects/DockerManager/app/__init__.py:76]
2019-06-20 12:45:20,555 ERROR: Exception on /load/undefined [GET] [in /Users/aisino/Projects/DockerManager/venv/lib/python3.7/site-packages/flask/app.py:1780]
Traceback (most recent call last):
  File "/Users/aisino/Projects/DockerManager/venv/lib/python3.7/site-packages/flask/app.py", line 2311, in wsgi_app
    response = self.full_dispatch_request()
  File "/Users/aisino/Projects/DockerManager/venv/lib/python3.7/site-packages/flask/app.py", line 1834, in full_dispatch_request
    rv = self.handle_user_exception(e)
  File "/Users/aisino/Projects/DockerManager/venv/lib/python3.7/site-packages/flask/app.py", line 1737, in handle_user_exception
    reraise(exc_type, exc_value, tb)
  File "/Users/aisino/Projects/DockerManager/venv/lib/python3.7/site-packages/flask/_compat.py", line 36, in reraise
    raise value
  File "/Users/aisino/Projects/DockerManager/venv/lib/python3.7/site-packages/flask/app.py", line 1832, in full_dispatch_request
    rv = self.dispatch_request()
  File "/Users/aisino/Projects/DockerManager/venv/lib/python3.7/site-packages/flask/app.py", line 1818, in dispatch_request
    return self.view_functions[rule.endpoint](**req.view_args)
  File "/Users/aisino/Projects/DockerManager/venv/lib/python3.7/site-packages/flask_login/utils.py", line 261, in decorated_view
    return func(*args, **kwargs)
  File "/Users/aisino/Projects/DockerManager/app/main/routes.py", line 51, in load_endpoint
    mode = services.get_endpoint_mode(endpoint_id)
  File "/Users/aisino/Projects/DockerManager/app/endpoint/services.py", line 58, in get_endpoint_mode
    client = docker_client(endpoint.url)
AttributeError: 'NoneType' object has no attribute 'url'
2019-06-20 12:45:55,637 INFO: Aisino Docker Manager startup [in /Users/aisino/Projects/DockerManager/app/__init__.py:76]
