2019-06-21 14:14:01,729 ERROR: Exception on /auth/login [POST] [in /Users/aisino/Projects/DockerManager/venv/lib/python3.7/site-packages/flask/app.py:1780]
Traceback (most recent call last):
  File "/Users/aisino/Projects/DockerManager/venv/lib/python3.7/site-packages/sqlalchemy/engine/base.py", line 1244, in _execute_context
    cursor, statement, parameters, context
  File "/Users/aisino/Projects/DockerManager/venv/lib/python3.7/site-packages/sqlalchemy/engine/default.py", line 550, in do_execute
    cursor.execute(statement, parameters)
  File "/Users/aisino/Projects/DockerManager/venv/lib/python3.7/site-packages/pymysql/cursors.py", line 170, in execute
    result = self._query(query)
  File "/Users/aisino/Projects/DockerManager/venv/lib/python3.7/site-packages/pymysql/cursors.py", line 328, in _query
    conn.query(q)
  File "/Users/aisino/Projects/DockerManager/venv/lib/python3.7/site-packages/pymysql/connections.py", line 517, in query
    self._affected_rows = self._read_query_result(unbuffered=unbuffered)
  File "/Users/aisino/Projects/DockerManager/venv/lib/python3.7/site-packages/pymysql/connections.py", line 732, in _read_query_result
    result.read()
  File "/Users/aisino/Projects/DockerManager/venv/lib/python3.7/site-packages/pymysql/connections.py", line 1075, in read
    first_packet = self.connection._read_packet()
  File "/Users/aisino/Projects/DockerManager/venv/lib/python3.7/site-packages/pymysql/connections.py", line 657, in _read_packet
    packet_header = self._read_bytes(4)
  File "/Users/aisino/Projects/DockerManager/venv/lib/python3.7/site-packages/pymysql/connections.py", line 707, in _read_bytes
    CR.CR_SERVER_LOST, "Lost connection to MySQL server during query")
pymysql.err.OperationalError: (2013, 'Lost connection to MySQL server during query')

The above exception was the direct cause of the following exception:

Traceback (most recent call last):
  File "/Users/aisino/Projects/DockerManager/venv/lib/python3.7/site-packages/flask/app.py", line 2311, in wsgi_app
    response = self.full_dispatch_request()
  File "/Users/aisino/Projects/DockerManager/venv/lib/python3.7/site-packages/flask/app.py", line 1834, in full_dispatch_request
    rv = self.handle_user_exception(e)
  File "/Users/aisino/Projects/DockerManager/venv/lib/python3.7/site-packages/flask/app.py", line 1737, in handle_user_exception
    reraise(exc_type, exc_value, tb)
  File "/Users/aisino/Projects/DockerManager/venv/lib/python3.7/site-packages/flask/_compat.py", line 36, in reraise
    raise value
  File "/Users/aisino/Projects/DockerManager/venv/lib/python3.7/site-packages/flask/app.py", line 1832, in full_dispatch_request
    rv = self.dispatch_request()
  File "/Users/aisino/Projects/DockerManager/venv/lib/python3.7/site-packages/flask/app.py", line 1818, in dispatch_request
    return self.view_functions[rule.endpoint](**req.view_args)
  File "/Users/aisino/Projects/DockerManager/app/auth/routes.py", line 20, in login
    user = User.query.filter_by(email=form.email.data).first()
  File "/Users/aisino/Projects/DockerManager/venv/lib/python3.7/site-packages/sqlalchemy/orm/query.py", line 3221, in first
    ret = list(self[0:1])
  File "/Users/aisino/Projects/DockerManager/venv/lib/python3.7/site-packages/sqlalchemy/orm/query.py", line 3011, in __getitem__
    return list(res)
  File "/Users/aisino/Projects/DockerManager/venv/lib/python3.7/site-packages/sqlalchemy/orm/query.py", line 3323, in __iter__
    return self._execute_and_instances(context)
  File "/Users/aisino/Projects/DockerManager/venv/lib/python3.7/site-packages/sqlalchemy/orm/query.py", line 3348, in _execute_and_instances
    result = conn.execute(querycontext.statement, self._params)
  File "/Users/aisino/Projects/DockerManager/venv/lib/python3.7/site-packages/sqlalchemy/engine/base.py", line 988, in execute
    return meth(self, multiparams, params)
  File "/Users/aisino/Projects/DockerManager/venv/lib/python3.7/site-packages/sqlalchemy/sql/elements.py", line 287, in _execute_on_connection
    return connection._execute_clauseelement(self, multiparams, params)
  File "/Users/aisino/Projects/DockerManager/venv/lib/python3.7/site-packages/sqlalchemy/engine/base.py", line 1107, in _execute_clauseelement
    distilled_params,
  File "/Users/aisino/Projects/DockerManager/venv/lib/python3.7/site-packages/sqlalchemy/engine/base.py", line 1248, in _execute_context
    e, statement, parameters, cursor, context
  File "/Users/aisino/Projects/DockerManager/venv/lib/python3.7/site-packages/sqlalchemy/engine/base.py", line 1466, in _handle_dbapi_exception
    util.raise_from_cause(sqlalchemy_exception, exc_info)
  File "/Users/aisino/Projects/DockerManager/venv/lib/python3.7/site-packages/sqlalchemy/util/compat.py", line 383, in raise_from_cause
    reraise(type(exception), exception, tb=exc_tb, cause=cause)
  File "/Users/aisino/Projects/DockerManager/venv/lib/python3.7/site-packages/sqlalchemy/util/compat.py", line 128, in reraise
    raise value.with_traceback(tb)
  File "/Users/aisino/Projects/DockerManager/venv/lib/python3.7/site-packages/sqlalchemy/engine/base.py", line 1244, in _execute_context
    cursor, statement, parameters, context
  File "/Users/aisino/Projects/DockerManager/venv/lib/python3.7/site-packages/sqlalchemy/engine/default.py", line 550, in do_execute
    cursor.execute(statement, parameters)
  File "/Users/aisino/Projects/DockerManager/venv/lib/python3.7/site-packages/pymysql/cursors.py", line 170, in execute
    result = self._query(query)
  File "/Users/aisino/Projects/DockerManager/venv/lib/python3.7/site-packages/pymysql/cursors.py", line 328, in _query
    conn.query(q)
  File "/Users/aisino/Projects/DockerManager/venv/lib/python3.7/site-packages/pymysql/connections.py", line 517, in query
    self._affected_rows = self._read_query_result(unbuffered=unbuffered)
  File "/Users/aisino/Projects/DockerManager/venv/lib/python3.7/site-packages/pymysql/connections.py", line 732, in _read_query_result
    result.read()
  File "/Users/aisino/Projects/DockerManager/venv/lib/python3.7/site-packages/pymysql/connections.py", line 1075, in read
    first_packet = self.connection._read_packet()
  File "/Users/aisino/Projects/DockerManager/venv/lib/python3.7/site-packages/pymysql/connections.py", line 657, in _read_packet
    packet_header = self._read_bytes(4)
  File "/Users/aisino/Projects/DockerManager/venv/lib/python3.7/site-packages/pymysql/connections.py", line 707, in _read_bytes
    CR.CR_SERVER_LOST, "Lost connection to MySQL server during query")
sqlalchemy.exc.OperationalError: (pymysql.err.OperationalError) (2013, 'Lost connection to MySQL server during query')
[SQL: SELECT user.id AS user_id, user.email AS user_email, user.password_hash AS user_password_hash, user.create_date AS user_create_date, user.last_visit AS user_last_visit, user.active AS user_active, user.role_id AS user_role_id 
FROM user 
WHERE user.email = %(email_1)s 
 LIMIT %(param_1)s]
[parameters: {'email_1': 'xuhang@aisino.com', 'param_1': 1}]
(Background on this error at: http://sqlalche.me/e/e3q8)
2019-06-21 14:14:11,407 INFO: request login [in /Users/aisino/Projects/DockerManager/app/auth/routes.py:15]
2019-06-21 14:14:11,745 INFO: User: xuhang was login [in /Users/aisino/Projects/DockerManager/app/auth/routes.py:28]
2019-06-21 14:32:18,373 INFO: Aisino Docker Manager startup [in /Users/aisino/Projects/DockerManager/app/__init__.py:79]
2019-06-21 14:33:18,337 ERROR: Exception on /image/remove [POST] [in /Users/aisino/Projects/DockerManager/venv/lib/python3.7/site-packages/flask/app.py:1780]
Traceback (most recent call last):
  File "/Users/aisino/Projects/DockerManager/venv/lib/python3.7/site-packages/flask/app.py", line 2311, in wsgi_app
    response = self.full_dispatch_request()
  File "/Users/aisino/Projects/DockerManager/venv/lib/python3.7/site-packages/flask/app.py", line 1834, in full_dispatch_request
    rv = self.handle_user_exception(e)
  File "/Users/aisino/Projects/DockerManager/venv/lib/python3.7/site-packages/flask/app.py", line 1737, in handle_user_exception
    reraise(exc_type, exc_value, tb)
  File "/Users/aisino/Projects/DockerManager/venv/lib/python3.7/site-packages/flask/_compat.py", line 36, in reraise
    raise value
  File "/Users/aisino/Projects/DockerManager/venv/lib/python3.7/site-packages/flask/app.py", line 1832, in full_dispatch_request
    rv = self.dispatch_request()
  File "/Users/aisino/Projects/DockerManager/venv/lib/python3.7/site-packages/flask/app.py", line 1818, in dispatch_request
    return self.view_functions[rule.endpoint](**req.view_args)
  File "/Users/aisino/Projects/DockerManager/venv/lib/python3.7/site-packages/flask_login/utils.py", line 261, in decorated_view
    return func(*args, **kwargs)
  File "/Users/aisino/Projects/DockerManager/app/image/routes.py", line 61, in remove_images
    result = services.remove_images(endpoint_id, image_hashs)
  File "/Users/aisino/Projects/DockerManager/app/image/services.py", line 126, in remove_images
    client = docker_client(url)
  File "/Users/aisino/Projects/DockerManager/app/utils/docker.py", line 5, in docker_client
    return docker.DockerClient(base_url=url, version='auto', timeout=5)
  File "/Users/aisino/Projects/DockerManager/venv/lib/python3.7/site-packages/docker/client.py", line 40, in __init__
    self.api = APIClient(*args, **kwargs)
  File "/Users/aisino/Projects/DockerManager/venv/lib/python3.7/site-packages/docker/api/client.py", line 133, in __init__
    base_url, IS_WINDOWS_PLATFORM, tls=bool(tls)
  File "/Users/aisino/Projects/DockerManager/venv/lib/python3.7/site-packages/docker/utils/utils.py", line 225, in parse_host
    if not addr or addr.strip() == 'unix://':
AttributeError: 'Endpoint' object has no attribute 'strip'
2019-06-21 14:34:05,838 INFO: Aisino Docker Manager startup [in /Users/aisino/Projects/DockerManager/app/__init__.py:79]
