2019-06-21 13:45:18,633 ERROR: Exception on /image/pull [POST] [in /Users/aisino/Projects/DockerManager/venv/lib/python3.7/site-packages/flask/app.py:1780]
Traceback (most recent call last):
  File "/Users/aisino/Projects/DockerManager/venv/lib/python3.7/site-packages/sqlalchemy/engine/base.py", line 1244, in _execute_context
    cursor, statement, parameters, context
  File "/Users/aisino/Projects/DockerManager/venv/lib/python3.7/site-packages/sqlalchemy/engine/default.py", line 550, in do_execute
    cursor.execute(statement, parameters)
  File "/Users/aisino/Projects/DockerManager/venv/lib/python3.7/site-packages/pymysql/cursors.py", line 170, in execute
    result = self._query(query)
  File "/Users/aisino/Projects/DockerManager/venv/lib/python3.7/site-packages/pymysql/cursors.py", line 328, in _query
    conn.query(q)
  File "/Users/aisino/Projects/DockerManager/venv/lib/python3.7/site-packages/pymysql/connections.py", line 517, in query
    self._affected_rows = self._read_query_result(unbuffered=unbuffered)
  File "/Users/aisino/Projects/DockerManager/venv/lib/python3.7/site-packages/pymysql/connections.py", line 732, in _read_query_result
    result.read()
  File "/Users/aisino/Projects/DockerManager/venv/lib/python3.7/site-packages/pymysql/connections.py", line 1075, in read
    first_packet = self.connection._read_packet()
  File "/Users/aisino/Projects/DockerManager/venv/lib/python3.7/site-packages/pymysql/connections.py", line 657, in _read_packet
    packet_header = self._read_bytes(4)
  File "/Users/aisino/Projects/DockerManager/venv/lib/python3.7/site-packages/pymysql/connections.py", line 707, in _read_bytes
    CR.CR_SERVER_LOST, "Lost connection to MySQL server during query")
pymysql.err.OperationalError: (2013, 'Lost connection to MySQL server during query')

The above exception was the direct cause of the following exception:

Traceback (most recent call last):
  File "/Users/aisino/Projects/DockerManager/venv/lib/python3.7/site-packages/flask/app.py", line 2311, in wsgi_app
    response = self.full_dispatch_request()
  File "/Users/aisino/Projects/DockerManager/venv/lib/python3.7/site-packages/flask/app.py", line 1834, in full_dispatch_request
    rv = self.handle_user_exception(e)
  File "/Users/aisino/Projects/DockerManager/venv/lib/python3.7/site-packages/flask/app.py", line 1737, in handle_user_exception
    reraise(exc_type, exc_value, tb)
  File "/Users/aisino/Projects/DockerManager/venv/lib/python3.7/site-packages/flask/_compat.py", line 36, in reraise
    raise value
  File "/Users/aisino/Projects/DockerManager/venv/lib/python3.7/site-packages/flask/app.py", line 1830, in full_dispatch_request
    rv = self.preprocess_request()
  File "/Users/aisino/Projects/DockerManager/venv/lib/python3.7/site-packages/flask/app.py", line 2106, in preprocess_request
    rv = func()
  File "/Users/aisino/Projects/DockerManager/app/main/routes.py", line 12, in before_request
    if current_user.is_authenticated:
  File "/Users/aisino/Projects/DockerManager/venv/lib/python3.7/site-packages/werkzeug/local.py", line 348, in __getattr__
    return getattr(self._get_current_object(), name)
  File "/Users/aisino/Projects/DockerManager/venv/lib/python3.7/site-packages/werkzeug/local.py", line 307, in _get_current_object
    return self.__local()
  File "/Users/aisino/Projects/DockerManager/venv/lib/python3.7/site-packages/flask_login/utils.py", line 26, in <lambda>
    current_user = LocalProxy(lambda: _get_user())
  File "/Users/aisino/Projects/DockerManager/venv/lib/python3.7/site-packages/flask_login/utils.py", line 335, in _get_user
    current_app.login_manager._load_user()
  File "/Users/aisino/Projects/DockerManager/venv/lib/python3.7/site-packages/flask_login/login_manager.py", line 359, in _load_user
    return self.reload_user()
  File "/Users/aisino/Projects/DockerManager/venv/lib/python3.7/site-packages/flask_login/login_manager.py", line 321, in reload_user
    user = self.user_callback(user_id)
  File "/Users/aisino/Projects/DockerManager/app/models.py", line 133, in load_user
    return User.query.get(int(user_id))
  File "/Users/aisino/Projects/DockerManager/venv/lib/python3.7/site-packages/sqlalchemy/orm/query.py", line 959, in get
    return self._get_impl(ident, loading.load_on_pk_identity)
  File "/Users/aisino/Projects/DockerManager/venv/lib/python3.7/site-packages/sqlalchemy/orm/query.py", line 1069, in _get_impl
    return db_load_fn(self, primary_key_identity)
  File "/Users/aisino/Projects/DockerManager/venv/lib/python3.7/site-packages/sqlalchemy/orm/loading.py", line 282, in load_on_pk_identity
    return q.one()
  File "/Users/aisino/Projects/DockerManager/venv/lib/python3.7/site-packages/sqlalchemy/orm/query.py", line 3281, in one
    ret = self.one_or_none()
  File "/Users/aisino/Projects/DockerManager/venv/lib/python3.7/site-packages/sqlalchemy/orm/query.py", line 3250, in one_or_none
    ret = list(self)
  File "/Users/aisino/Projects/DockerManager/venv/lib/python3.7/site-packages/sqlalchemy/orm/query.py", line 3323, in __iter__
    return self._execute_and_instances(context)
  File "/Users/aisino/Projects/DockerManager/venv/lib/python3.7/site-packages/sqlalchemy/orm/query.py", line 3348, in _execute_and_instances
    result = conn.execute(querycontext.statement, self._params)
  File "/Users/aisino/Projects/DockerManager/venv/lib/python3.7/site-packages/sqlalchemy/engine/base.py", line 988, in execute
    return meth(self, multiparams, params)
  File "/Users/aisino/Projects/DockerManager/venv/lib/python3.7/site-packages/sqlalchemy/sql/elements.py", line 287, in _execute_on_connection
    return connection._execute_clauseelement(self, multiparams, params)
  File "/Users/aisino/Projects/DockerManager/venv/lib/python3.7/site-packages/sqlalchemy/engine/base.py", line 1107, in _execute_clauseelement
    distilled_params,
  File "/Users/aisino/Projects/DockerManager/venv/lib/python3.7/site-packages/sqlalchemy/engine/base.py", line 1248, in _execute_context
    e, statement, parameters, cursor, context
  File "/Users/aisino/Projects/DockerManager/venv/lib/python3.7/site-packages/sqlalchemy/engine/base.py", line 1466, in _handle_dbapi_exception
    util.raise_from_cause(sqlalchemy_exception, exc_info)
  File "/Users/aisino/Projects/DockerManager/venv/lib/python3.7/site-packages/sqlalchemy/util/compat.py", line 383, in raise_from_cause
    reraise(type(exception), exception, tb=exc_tb, cause=cause)
  File "/Users/aisino/Projects/DockerManager/venv/lib/python3.7/site-packages/sqlalchemy/util/compat.py", line 128, in reraise
    raise value.with_traceback(tb)
  File "/Users/aisino/Projects/DockerManager/venv/lib/python3.7/site-packages/sqlalchemy/engine/base.py", line 1244, in _execute_context
    cursor, statement, parameters, context
  File "/Users/aisino/Projects/DockerManager/venv/lib/python3.7/site-packages/sqlalchemy/engine/default.py", line 550, in do_execute
    cursor.execute(statement, parameters)
  File "/Users/aisino/Projects/DockerManager/venv/lib/python3.7/site-packages/pymysql/cursors.py", line 170, in execute
    result = self._query(query)
  File "/Users/aisino/Projects/DockerManager/venv/lib/python3.7/site-packages/pymysql/cursors.py", line 328, in _query
    conn.query(q)
  File "/Users/aisino/Projects/DockerManager/venv/lib/python3.7/site-packages/pymysql/connections.py", line 517, in query
    self._affected_rows = self._read_query_result(unbuffered=unbuffered)
  File "/Users/aisino/Projects/DockerManager/venv/lib/python3.7/site-packages/pymysql/connections.py", line 732, in _read_query_result
    result.read()
  File "/Users/aisino/Projects/DockerManager/venv/lib/python3.7/site-packages/pymysql/connections.py", line 1075, in read
    first_packet = self.connection._read_packet()
  File "/Users/aisino/Projects/DockerManager/venv/lib/python3.7/site-packages/pymysql/connections.py", line 657, in _read_packet
    packet_header = self._read_bytes(4)
  File "/Users/aisino/Projects/DockerManager/venv/lib/python3.7/site-packages/pymysql/connections.py", line 707, in _read_bytes
    CR.CR_SERVER_LOST, "Lost connection to MySQL server during query")
sqlalchemy.exc.OperationalError: (pymysql.err.OperationalError) (2013, 'Lost connection to MySQL server during query')
[SQL: SELECT user.id AS user_id, user.email AS user_email, user.password_hash AS user_password_hash, user.create_date AS user_create_date, user.last_visit AS user_last_visit, user.active AS user_active, user.role_id AS user_role_id 
FROM user 
WHERE user.id = %(param_1)s]
[parameters: {'param_1': 1}]
(Background on this error at: http://sqlalche.me/e/e3q8)
2019-06-21 13:45:54,064 ERROR: Pull image: registry.docker-cn.com/library/alpine:3.9 fail, error: Error while fetching server API version: HTTPConnectionPool(host='192.168.23.26', port=2375): Max retries exceeded with url: /version (Caused by ConnectTimeoutError(<urllib3.connection.HTTPConnection object at 0x11072f438>, 'Connection to 192.168.23.26 timed out. (connect timeout=5)')), user: xuhang [in /Users/aisino/Projects/DockerManager/app/image/services.py:93]
2019-06-21 13:46:47,069 INFO: Start to pull image: registry.docker-cn.com/library/alpine:3.9, user: xuhang [in /Users/aisino/Projects/DockerManager/app/image/services.py:88]
2019-06-21 13:47:02,090 ERROR: Pull image: registry.docker-cn.com/library/alpine:3.9 fail, error: 500 Server Error: Internal Server Error ("Get https://registry.docker-cn.com/v2/: net/http: request canceled while waiting for connection (Client.Timeout exceeded while awaiting headers)"), user: xuhang [in /Users/aisino/Projects/DockerManager/app/image/services.py:93]
2019-06-21 14:13:35,894 INFO: request login [in /Users/aisino/Projects/DockerManager/app/auth/routes.py:15]
2019-06-21 14:13:56,948 INFO: request login [in /Users/aisino/Projects/DockerManager/app/auth/routes.py:15]
2019-06-21 14:14:01,725 INFO: request login [in /Users/aisino/Projects/DockerManager/app/auth/routes.py:15]
