2019-06-21 13:03:17,185 ERROR: Exception on /image/pull [POST] [in /Users/aisino/Projects/DockerManager/venv/lib/python3.7/site-packages/flask/app.py:1780]
Traceback (most recent call last):
  File "/Users/aisino/Projects/DockerManager/venv/lib/python3.7/site-packages/flask/app.py", line 2311, in wsgi_app
    response = self.full_dispatch_request()
  File "/Users/aisino/Projects/DockerManager/venv/lib/python3.7/site-packages/flask/app.py", line 1834, in full_dispatch_request
    rv = self.handle_user_exception(e)
  File "/Users/aisino/Projects/DockerManager/venv/lib/python3.7/site-packages/flask/app.py", line 1737, in handle_user_exception
    reraise(exc_type, exc_value, tb)
  File "/Users/aisino/Projects/DockerManager/venv/lib/python3.7/site-packages/flask/_compat.py", line 36, in reraise
    raise value
  File "/Users/aisino/Projects/DockerManager/venv/lib/python3.7/site-packages/flask/app.py", line 1832, in full_dispatch_request
    rv = self.dispatch_request()
  File "/Users/aisino/Projects/DockerManager/venv/lib/python3.7/site-packages/flask/app.py", line 1818, in dispatch_request
    return self.view_functions[rule.endpoint](**req.view_args)
  File "/Users/aisino/Projects/DockerManager/venv/lib/python3.7/site-packages/flask_login/utils.py", line 261, in decorated_view
    return func(*args, **kwargs)
  File "/Users/aisino/Projects/DockerManager/app/image/routes.py", line 45, in pull_image
    image = services.pull_image(endpoint_id, form)
  File "/Users/aisino/Projects/DockerManager/app/image/services.py", line 88, in pull_image
    current_user.logger.info('*****************************' + repo)
  File "/Users/aisino/Projects/DockerManager/venv/lib/python3.7/site-packages/werkzeug/local.py", line 348, in __getattr__
    return getattr(self._get_current_object(), name)
AttributeError: 'User' object has no attribute 'logger'
2019-06-21 13:03:45,526 INFO: Aisino Docker Manager startup [in /Users/aisino/Projects/DockerManager/app/__init__.py:79]
2019-06-21 13:04:46,799 INFO: *****************************<Registry 1>/library/alpine [in /Users/aisino/Projects/DockerManager/app/image/services.py:88]
2019-06-21 13:04:46,806 ERROR: Pull image: <Registry 1>/library/alpine:3.9 fail, error: 400 Client Error: Bad Request ("invalid reference format: repository name must be lowercase"), user: xuhang [in /Users/aisino/Projects/DockerManager/app/image/services.py:93]
2019-06-21 13:05:35,231 INFO: Aisino Docker Manager startup [in /Users/aisino/Projects/DockerManager/app/__init__.py:79]
2019-06-21 13:07:37,816 INFO: Aisino Docker Manager startup [in /Users/aisino/Projects/DockerManager/app/__init__.py:79]
2019-06-21 13:07:47,632 INFO: Start to pull image: registry.docker-cn.com/library/alpine:3.9, user: xuhang [in /Users/aisino/Projects/DockerManager/app/image/services.py:88]
2019-06-21 13:08:02,679 ERROR: Pull image: registry.docker-cn.com/library/alpine:3.9 fail, error: 500 Server Error: Internal Server Error ("Get https://registry.docker-cn.com/v2/: net/http: request canceled while waiting for connection (Client.Timeout exceeded while awaiting headers)"), user: xuhang [in /Users/aisino/Projects/DockerManager/app/image/services.py:93]
